Workbook

Sheet LibFilters3 filterPanelIds
A1: LibFilters-3.0 filterPanelIds are global constants in table _G which can be used to identify an actively shown UI, and (Un)Register custom filterFunctions to them, to hide items at these inventories/lists.
A2: LibFilters filterPanelId constant | B2: Value | C2: Descritption | D2: Comment / Implementation notes | E2: FilterFunction parameters
A3: LF_ALCHEMY_CREATION | B3: 19 | C3: Alchemy potion or poison creation | E3: bagId, slotIndex
A4: LF_BANK_DEPOSIT | B4: 3 | C4: Player bank Deposit | E4: slotData (with bagId and slotIndex in the slotData)
A5: LF_BANK_WITHDRAW | B5: 2 | C5: Player bank Withdraw | E5: slotData (with bagId and slotIndex in the slotData)
A6: LF_CRAFTBAG | B6: 26 | C6: CraftBag | E6: slotData (with bagId and slotIndex in the slotData, but slotIndex is actually the item's itemId!!!)
A7: LF_ENCHANTING_CREATION | B7: 20 | C7: Enchanting table's glyph creation | E7: bagId, slotIndex
A8: LF_ENCHANTING_EXTRACTION | B8: 21 | C8: Enchanting table's glyph extraction | D8: Universal deconstruction is automatically detected and uses the same LibFilter's filterPanelIds, just enhances some API functions by returning the currently active UniversalDeconstruction UI's tab "all", "armor", "weapons", "enchanting", "jewelry" | E8: bagId, slotIndex
A9: LF_FENCE_LAUNDER | B9: 25 | C9: Fence vendor launder | E9: slotData (with bagId and slotIndex in the slotData)
A10: LF_FENCE_SELL | B10: 24 | C10: Fence vendor sell | E10: slotData (with bagId and slotIndex in the slotData)
A11: LF_FURNITURE_VAULT_DEPOSIT | B11: 41 | C11: Furniture vault Deposit (ESO+ Housing) | E11: slotData (with bagId and slotIndex in the slotData)
A12: LF_FURNITURE_VAULT_WITHDRAW | B12: 40 | C12: Furniture vault Withdraw (ESO+ Housing) | E12: slotData (with bagId and slotIndex in the slotData)
A13: LF_GUILDBANK_DEPOSIT | B13: 5 | C13: Guildbank Deposit | E13: slotData (with bagId and slotIndex in the slotData)
A14: LF_GUILDBANK_WITHDRAW | B14: 4 | C14: Guildbank Withdraw | E14: slotData (with bagId and slotIndex in the slotData)
A15: LF_GUILDSTORE_BROWSE | B15: 10 | C15: Guildstore / Tradinghouse Search | D15: Currently not implemented | E15: unknown, probably slotData (with searchr esults list item's index)
A16: LF_GUILDSTORE_SELL | B16: 11 | C16: Guildstore / Tradinghouse Sell | E16: slotData (with bagId and slotIndex in the slotData)
A17: LF_HOUSE_BANK_DEPOSIT | B17: 30 | C17: House bank 1 to 10 Deposit | E17: slotData (with bagId and slotIndex in the slotData)
A18: LF_HOUSE_BANK_WITHDRAW | B18: 29 | C18: House bank 1 to 10 Withdraw | E18: slotData (with bagId and slotIndex in the slotData)
A19: LF_INVENTORY | B19: 1 | C19: Player inventory | E19: slotData (with bagId and slotIndex in the slotData)
A20: LF_INVENTORY_COMPANION | B20: 39 | C20: Companion inventory (Equipment) | E20: slotData (with bagId and slotIndex in the slotData)
A21: LF_INVENTORY_QUEST | B21: 38 | C21: Inventory quest items | E21: slotData (with bagId and slotIndex in the slotData)
A22: LF_INVENTORY_VENGEANCE | B22: 42 | C22: Cyrodiil Vengeance campaign inventory | E22: slotData (with bagId and slotIndex in the slotData)
A23: LF_JEWELRY_CREATION | B23: 32 | C23: Jewelry crafting creation | D23: Currently not implemented | E23: unknown - new item will be created here so possibly slotData?
A24: LF_JEWELRY_DECONSTRUCT | B24: 33 | C24: Jewelry crafting deconstruction | D24: Universal deconstruction is automatically detected and uses the same LibFilter's filterPanelIds, just enhances some API functions by returning the currently active UniversalDeconstruction UI's tab "all", "armor", "weapons", "enchanting", "jewelry" filterPanelId will be checked via GetCraftingInteractionType(), if this returns jewelry then it will be the LF_JEWELRY_*, else LF_SMITHING_* | E24: bagId, slotIndex
A25: LF_JEWELRY_IMPROVEMENT | B25: 34 | C25: Jewelry crafting improvement | D25: filterPanelId will be checked via GetCraftingInteractionType(), if this returns jewelry then it will be the LF_JEWELRY_*, else LF_SMITHING_* | E25: bagId, slotIndex
A26: LF_JEWELRY_REFINE | B26: 31 | C26: Jewelry crafting refinement | D26: filterPanelId will be checked via GetCraftingInteractionType(), if this returns jewelry then it will be the LF_JEWELRY_*, else LF_SMITHING_* | E26: bagId, slotIndex
A27: LF_JEWELRY_RESEARCH | B27: 35 | C27: Jewelry crafting research trait list | D27: filterPanelId will be checked via GetCraftingInteractionType(), if this returns jewelry then it will be the LF_JEWELRY_*, else LF_SMITHING_* | E27: bagId, slotIndex
A28: LF_JEWELRY_RESEARCH_DIALOG | B28: 37 | C28: Jewelry crafting research item selection popup | D28: filterPanelId will be checked via GetCraftingInteractionType(), if this returns jewelry then it will be the LF_JEWELRY_*, else LF_SMITHING_* | E28: bagId, slotIndex
A29: LF_MAIL_SEND | B29: 12 | C29: Mail send | E29: slotData (with bagId and slotIndex in the slotData)
A30: LF_PROVISIONING_BREW | B30: 23 | C30: Provisioner brewing drinks | D30: Currently not implemented | E30: unknown - new item will be created here so possibly slotData?
A31: LF_PROVISIONING_COOK | B31: 22 | C31: Provisioner cooking food | D31: Currently not implemented | E31: unknown - new item will be created here so possibly slotData?
A32: LF_QUICKSLOT | B32: 27 | C32: Quickslot wheel's inventory | E32: slotData (with bagId = BAG_BACKPACK and slotIndex in the slotData)
A33: LF_RETRAIT | B33: 28 | C33: Retrait station's retrait panel | E33: bagId, slotIndex
A34: LF_SMITHING_CREATION | B34: 15 | C34: Smithing creation | D34: Currently not implemented | E34: unknown - new item will be created here so possibly slotData?
A35: LF_SMITHING_DECONSTRUCT | B35: 16 | C35: Smithing deconstruction | D35: Universal deconstruction is automatically detected and uses the same LibFilter's filterPanelIds, just enhances some API functions by returning the currently active UniversalDeconstruction UI's tab "all", "armor", "weapons", "enchanting", "jewelry" filterPanelId will be checked via GetCraftingInteractionType(), if this returns jewelry then it will be the LF_JEWELRY_*, else LF_SMITHING_* | E35: bagId, slotIndex
A36: LF_SMITHING_IMPROVEMENT | B36: 17 | C36: Smithing improvement | D36: filterPanelId will be checked via GetCraftingInteractionType(), if this returns jewelry then it will be the LF_JEWELRY_*, else LF_SMITHING_* | E36: bagId, slotIndex
A37: LF_SMITHING_REFINE | B37: 14 | C37: Smithing refinement | D37: filterPanelId will be checked via GetCraftingInteractionType(), if this returns jewelry then it will be the LF_JEWELRY_*, else LF_SMITHING_* | E37: bagId, slotIndex
A38: LF_SMITHING_RESEARCH | B38: 18 | C38: Smithing research trait list | D38: filterPanelId will be checked via GetCraftingInteractionType(), if this returns jewelry then it will be the LF_JEWELRY_*, else LF_SMITHING_* | E38: bagId, slotIndex
A39: LF_SMITHING_RESEARCH_DIALOG | B39: 36 | C39: Smithing research item selection popup | D39: filterPanelId will be checked via GetCraftingInteractionType(), if this returns jewelry then it will be the LF_JEWELRY_*, else LF_SMITHING_* | E39: bagId, slotIndex
A40: LF_TRADE | B40: 13 | C40: Player to player trade | E40: slotData (with bagId and slotIndex in the slotData)
...

Sheet LibFilters3 .additionalFilter
A1: .additionalFilter is the function at e.g. an inventory fragment's layoutData/a scene/a fragment/an object/some userdata where the filterFunctions (vanilla + customs all combined in 1 function) are stored, that are executed once the inventory filters are executed (e.g. only show unbound items at the trade/mail panel, or only show non-stolen at bank deposit). LibFilters-3.0 uses these existing .additionalFilter, or adds them new to defined objects, or even new created custom fragments (Gamepad) so addons can Register their custom filterFunctions in add. to the vanilla filterFunction.
A2: LibFilters: filterPanelId | B2: UniversalDeconstruction tabName (UniversalDecon uses LF_SMITHING_DECONSTRUCT, LF_ENCHANTING_EXTRACTION and LF_JEWELRY_DECONSTRUCT but adds the current UniversalDecon. Tab) | C2: LibFilters filterPanelId: Description | D2: Implementation: Both/ Keyboard/ Gamepad | E2: LibFilters helper.lua implemented? | F2: LibFilters helper.lua: Vanilla filename of overwritten function | G2: LibFilters helper.lua: Overwritten function(s) | H2: LibFilters helper.lua: Object/Class/... of overwritten function | I2: Already uses vanilla .additionalFilter function? | J2: Object, where the .additionalFilter functions are stored? | K2: .additionalFilter object type (Object/Fragment/…) | L2: Object for .additionalFilter is vanilla? | M2: FilterPanelId .additionalFilter implemented? | N2: LibFilters Callback internally: "On SHOW" name Create via LibFilters3:CreateCallbackName(filterType, isShown, universalDeconSelectedTabNow) | O2: LibFilters Callback internally: "On HIDE" name Create via LibFilters3:CreateCallbackName(filterType, isShown, universalDeconSelectedTabNow) | P2: Callback SHOW/HIDE implemented? | Q2: Implementation comments/Important notes
A3: LF_ALCHEMY_CREATION | C3: =VLOOKUP(A3,'LibFilters3 filterPanelIds'!$A$3:$C$1000,3,FALSE) -> Alchemy potion or poison creation | D3: G | E3: X | F3: \esoui\ingame\crafting\sharedalchemy.lua | G3: ZO_Alchemy_DoesAlchemyItemPassFilter | H3: function itsself | J3: ALCHEMY_SCENE | K3: Scene | L3: X | M3: X | N3: ="LibFilters3"&"-shown-"&VLOOKUP(A3,'LibFilters3 filterPanelIds'!$A$3:$B$999,2) & "-" & IF(AND(B3<>"",B3<>"nil"),B3,"") -> LibFilters3-shown-19- | O3: ="LibFilters3"&"-hidden-"&VLOOKUP(A3,'LibFilters3 filterPanelIds'!$A$3:$B$999,2) & "-" & IF(AND(B3<>"",B3<>"nil"),B3,"") -> LibFilters3-hidden-19- | P3: X | Q3: Fallback to keyboard implementation (means: Uses same objects for .additionalFilter function)
A4: LF_ALCHEMY_CREATION | C4: =VLOOKUP(A4,'LibFilters3 filterPanelIds'!$A$3:$C$1000,3,FALSE) -> Alchemy potion or poison creation | D4: K | E4: X | F4: \esoui\ingame\crafting\sharedalchemy.lua | G4: ZO_Alchemy_DoesAlchemyItemPassFilter | H4: function itsself | J4: ALCHEMY_SCENE | K4: Scene | L4: X | M4: X | N4: ="LibFilters3"&"-shown-"&VLOOKUP(A4,'LibFilters3 filterPanelIds'!$A$3:$B$999,2) & "-" & IF(AND(B4<>"",B4<>"nil"),B4,"") -> LibFilters3-shown-19- | O4: ="LibFilters3"&"-hidden-"&VLOOKUP(A4,'LibFilters3 filterPanelIds'!$A$3:$B$999,2) & "-" & IF(AND(B4<>"",B4<>"nil"),B4,"") -> LibFilters3-hidden-19- | P4: X
A5: LF_BANK_DEPOSIT | C5: =VLOOKUP(A5,'LibFilters3 filterPanelIds'!$A$3:$C$1000,3,FALSE) -> Player bank Deposit | D5: G | E5: X | F5: \esoui\ingame\inventory\gamepad\inventorylist_gamepad.lua | G5: AddSlotDataToTable | H5: ZO_GamepadInventoryList | J5: LIBFILTERS3_BACKPACK_BANK_DEPOSIT_GAMEPAD_FRAGMENT.layoutData | K5: Custom LibFilters Fragment | M5: X | N5: ="LibFilters3"&"-shown-"&VLOOKUP(A5,'LibFilters3 filterPanelIds'!$A$3:$B$999,2) & "-" & IF(AND(B5<>"",B5<>"nil"),B5,"") -> LibFilters3-shown-3- | O5: ="LibFilters3"&"-hidden-"&VLOOKUP(A5,'LibFilters3 filterPanelIds'!$A$3:$B$999,2) & "-" & IF(AND(B5<>"",B5<>"nil"),B5,"") -> LibFilters3-hidden-3- | P5: X
A6: LF_BANK_DEPOSIT | C6: =VLOOKUP(A6,'LibFilters3 filterPanelIds'!$A$3:$C$1000,3,FALSE) -> Player bank Deposit | D6: K | G6: [+] None, uses vanilla Zos ZO_InventoryManager:ShouldAddSlotToList -> DoesSlotPassAdditionalFilter | I6: X | J6: BACKPACK_BANK_LAYOUT_FRAGMENT.layoutData | K6: Fragment | L6: X | M6: X | N6: ="LibFilters3"&"-shown-"&VLOOKUP(A6,'LibFilters3 filterPanelIds'!$A$3:$B$999,2) & "-" & IF(AND(B6<>"",B6<>"nil"),B6,"") -> LibFilters3-shown-3- | O6: ="LibFilters3"&"-hidden-"&VLOOKUP(A6,'LibFilters3 filterPanelIds'!$A$3:$B$999,2) & "-" & IF(AND(B6<>"",B6<>"nil"),B6,"") -> LibFilters3-hidden-3- | P6: X
A7: LF_BANK_WITHDRAW | C7: =VLOOKUP(A7,'LibFilters3 filterPanelIds'!$A$3:$C$1000,3,FALSE) -> Player bank Withdraw | D7: G | E7: X | F7: \esoui\ingame\inventory\gamepad\inventorylist_gamepad.lua | G7: AddSlotDataToTable | H7: ZO_GamepadInventoryList | J7: PLAYER_INVENTORIES.inventories[INVENTORY_BANK] | K7: table (Inventory) | L7: X | M7: X | N7: ="LibFilters3"&"-shown-"&VLOOKUP(A7,'LibFilters3 filterPanelIds'!$A$3:$B$999,2) & "-" & IF(AND(B7<>"",B7<>"nil"),B7,"") -> LibFilters3-shown-2- | O7: ="LibFilters3"&"-hidden-"&VLOOKUP(A7,'LibFilters3 filterPanelIds'!$A$3:$B$999,2) & "-" & IF(AND(B7<>"",B7<>"nil"),B7,"") -> LibFilters3-hidden-2- | P7: X | Q7: Fallback to keyboard implementation (means: Uses same objects for .additionalFilter function)
A8: LF_BANK_WITHDRAW | C8: =VLOOKUP(A8,'LibFilters3 filterPanelIds'!$A$3:$C$1000,3,FALSE) -> Player bank Withdraw | D8: K | G8: [+] None, uses vanilla Zos ZO_InventoryManager:ShouldAddSlotToList -> DoesSlotPassAdditionalFilter | I8: X | J8: PLAYER_INVENTORIES.inventories[INVENTORY_BANK] | K8: table (Inventory) | L8: X | M8: X | N8: ="LibFilters3"&"-shown-"&VLOOKUP(A8,'LibFilters3 filterPanelIds'!$A$3:$B$999,2) & "-" & IF(AND(B8<>"",B8<>"nil"),B8,"") -> LibFilters3-shown-2- | O8: ="LibFilters3"&"-hidden-"&VLOOKUP(A8,'LibFilters3 filterPanelIds'!$A$3:$B$999,2) & "-" & IF(AND(B8<>"",B8<>"nil"),B8,"") -> LibFilters3-hidden-2- | P8: X
A9: LF_CRAFTBAG | C9: =VLOOKUP(A9,'LibFilters3 filterPanelIds'!$A$3:$C$1000,3,FALSE) -> CraftBag | D9: G | E9: X | F9: \esoui\ingame\inventory\gamepad\inventorylist_gamepad.lua | G9: AddSlotDataToTable | H9: ZO_GamepadInventoryList | J9: LIBFILTERS3_BACKPACK_CRAFTBAG_GAMEPAD_FRAGMENT.layoutData | K9: table (Inventory) | M9: X | N9: ="LibFilters3"&"-shown-"&VLOOKUP(A9,'LibFilters3 filterPanelIds'!$A$3:$B$999,2) & "-" & IF(AND(B9<>"",B9<>"nil"),B9,"") -> LibFilters3-shown-26- | O9: ="LibFilters3"&"-hidden-"&VLOOKUP(A9,'LibFilters3 filterPanelIds'!$A$3:$B$999,2) & "-" & IF(AND(B9<>"",B9<>"nil"),B9,"") -> LibFilters3-hidden-26- | P9: X
A10: LF_CRAFTBAG | C10: =VLOOKUP(A10,'LibFilters3 filterPanelIds'!$A$3:$C$1000,3,FALSE) -> CraftBag | D10: K | G10: [+] None, uses vanilla Zos ZO_InventoryManager:ShouldAddSlotToList -> DoesSlotPassAdditionalFilter | I10: X | J10: PLAYER_INVENTORIES.inventories[INVENTORY_CRAFT_BAG] | K10: table (Inventory) | L10: X | M10: X | N10: ="LibFilters3"&"-shown-"&VLOOKUP(A10,'LibFilters3 filterPanelIds'!$A$3:$B$999,2) & "-" & IF(AND(B10<>"",B10<>"nil"),B10,"") -> LibFilters3-shown-26- | O10: ="LibFilters3"&"-hidden-"&VLOOKUP(A10,'LibFilters3 filterPanelIds'!$A$3:$B$999,2) & "-" & IF(AND(B10<>"",B10<>"nil"),B10,"") -> LibFilters3-hidden-26- | P10: X | Q10: PLAYER_INVENTORY.inventories[INVENTORY_CRAFT_BAG].additionalFilter gets updated each time from layoutData.additionalCraftBagFilter, as ZO_InventoryManager:ApplyBackpackLayout(layoutData) is called. Attention: As LF_INVENTORY and LF_CRAFTBAG both get hooked via fragment BACKPACK_MENU_BAR_LAYOUT_FRAGMENT it needs to be applied a fix at ZO_InventoryManager:ApplyBackpackLayout in order to update layoutData.LibFilters3_filterType with the correct filterType, LF_INVENTORY or LF_CRAFTBAG! See file LibFilters-3.0.lua, function hookNow Else the last hooked one (LF_CRAFTBAG) will be kept as layoutData.LibFilters3_filterType all the time and filtering wont properly work
A11: LF_ENCHANTING_CREATION | C11: =VLOOKUP(A11,'LibFilters3 filterPanelIds'!$A$3:$C$1000,3,FALSE) -> Enchanting table's glyph creation | D11: G | E11: X | F11: \esoui\ingame\crafting\sharedenchanting.lua | G11: ZO_Enchanting_DoesEnchantingItemPassFilter | H11: function itsself | J11: GAMEPAD_ENCHANTING_CREATION_SCENE | K11: Scene | L11: X | M11: X | N11: ="LibFilters3"&"-shown-"&VLOOKUP(A11,'LibFilters3 filterPanelIds'!$A$3:$B$999,2) & "-" & IF(AND(B11<>"",B11<>"nil"),B11,"") -> LibFilters3-shown-20- | O11: ="LibFilters3"&"-hidden-"&VLOOKUP(A11,'LibFilters3 filterPanelIds'!$A$3:$B$999,2) & "-" & IF(AND(B11<>"",B11<>"nil"),B11,"") -> LibFilters3-hidden-20- | P11: X
A12: LF_ENCHANTING_CREATION | C12: =VLOOKUP(A12,'LibFilters3 filterPanelIds'!$A$3:$C$1000,3,FALSE) -> Enchanting table's glyph creation | D12: K | E12: X | F12: \esoui\ingame\crafting\sharedenchanting.lua | G12: ZO_Enchanting_DoesEnchantingItemPassFilter | H12: function itsself | J12: GAMEPAD_ENCHANTING_CREATION_SCENE | K12: Scene | L12: X | M12: X | N12: ="LibFilters3"&"-shown-"&VLOOKUP(A12,'LibFilters3 filterPanelIds'!$A$3:$B$999,2) & "-" & IF(AND(B12<>"",B12<>"nil"),B12,"") -> LibFilters3-shown-20- | O12: ="LibFilters3"&"-hidden-"&VLOOKUP(A12,'LibFilters3 filterPanelIds'!$A$3:$B$999,2) & "-" & IF(AND(B12<>"",B12<>"nil"),B12,"") -> LibFilters3-hidden-20- | P12: X | Q12: Fallback to gamepad implementation (means: Uses same objects for .additionalFilter function)
A13: LF_ENCHANTING_EXTRACTION | B13: nil | C13: =VLOOKUP(A13,'LibFilters3 filterPanelIds'!$A$3:$C$1000,3,FALSE) -> Enchanting table's glyph extraction | D13: G | E13: X | F13: \esoui\ingame\crafting\sharedenchanting.lua | G13: ZO_Enchanting_DoesEnchantingItemPassFilter | H13: function itsself | J13: GAMEPAD_ENCHANTING_EXTRACTION_SCENE | K13: Scene | L13: X | M13: X | N13: ="LibFilters3"&"-shown-"&VLOOKUP(A13,'LibFilters3 filterPanelIds'!$A$3:$B$999,2) & "-" & IF(AND(B13<>"",B13<>"nil"),B13,"") -> LibFilters3-shown-21- | O13: ="LibFilters3"&"-hidden-"&VLOOKUP(A13,'LibFilters3 filterPanelIds'!$A$3:$B$999,2) & "-" & IF(AND(B13<>"",B13<>"nil"),B13,"") -> LibFilters3-hidden-21- | P13: X
A14: LF_ENCHANTING_EXTRACTION | B14: nil | C14: =VLOOKUP(A14,'LibFilters3 filterPanelIds'!$A$3:$C$1000,3,FALSE) -> Enchanting table's glyph extraction | D14: K | E14: X | F14: \esoui\ingame\crafting\sharedenchanting.lua | G14: ZO_Enchanting_DoesEnchantingItemPassFilter | H14: function itsself | J14: GAMEPAD_ENCHANTING_EXTRACTION_SCENE | K14: Scene | L14: X | M14: X | N14: ="LibFilters3"&"-shown-"&VLOOKUP(A14,'LibFilters3 filterPanelIds'!$A$3:$B$999,2) & "-" & IF(AND(B14<>"",B14<>"nil"),B14,"") -> LibFilters3-shown-21- | O14: ="LibFilters3"&"-hidden-"&VLOOKUP(A14,'LibFilters3 filterPanelIds'!$A$3:$B$999,2) & "-" & IF(AND(B14<>"",B14<>"nil"),B14,"") -> LibFilters3-hidden-21- | P14: X | Q14: Fallback to gamepad implementation (means: Uses same objects for .additionalFilter function)
A15: LF_ENCHANTING_EXTRACTION | B15: "enchantments" | C15: Universal Deconstruction Enchanting | D15: G | E15: X | F15: \esoui\ingame\crafting\universaldeconstructionpanel_shared.lua | G15: DoesItemPassFilter | H15: ZO_UniversalDeconstructionPanel_Shared | J15: GAMEPAD_ENCHANTING_EXTRACTION_SCENE | K15: Scene | L15: X | M15: X | N15: ="LibFilters3"&"-shown-"&VLOOKUP(A15,'LibFilters3 filterPanelIds'!$A$3:$B$999,2) & "-" & IF(AND(B15<>"",B15<>"nil"),B15,"") -> LibFilters3-shown-21-"enchantments" | O15: ="LibFilters3"&"-hidden-"&VLOOKUP(A15,'LibFilters3 filterPanelIds'!$A$3:$B$999,2) & "-" & IF(AND(B15<>"",B15<>"nil"),B15,"") -> LibFilters3-hidden-21-"enchantments" | P15: X
A16: LF_ENCHANTING_EXTRACTION | B16: "enchantments" | C16: Universal Deconstruction Enchanting | D16: K | E16: X | F16: \esoui\ingame\crafting\universaldeconstructionpanel_shared.lua | G16: DoesItemPassFilter | H16: ZO_UniversalDeconstructionPanel_Shared | J16: GAMEPAD_ENCHANTING_EXTRACTION_SCENE | K16: Scene | L16: X | M16: X | N16: ="LibFilters3"&"-shown-"&VLOOKUP(A16,'LibFilters3 filterPanelIds'!$A$3:$B$999,2) & "-" & IF(AND(B16<>"",B16<>"nil"),B16,"") -> LibFilters3-shown-21-"enchantments" | O16: ="LibFilters3"&"-hidden-"&VLOOKUP(A16,'LibFilters3 filterPanelIds'!$A$3:$B$999,2) & "-" & IF(AND(B16<>"",B16<>"nil"),B16,"") -> LibFilters3-hidden-21-"enchantments" | P16: X | Q16: Fallback to gamepad implementation (means: Uses same objects for .additionalFilter function)
A17: LF_FENCE_LAUNDER | C17: =VLOOKUP(A17,'LibFilters3 filterPanelIds'!$A$3:$C$1000,3,FALSE) -> Fence vendor launder | D17: G | E17: X | F17: \esoui\ingame\storewindow\gamepad\storewindow_gamepad_util.lua | G17: updateFunc | H17: STORE_WINDOW_GAMEPAD.components[ZO_MODE_STORE_LAUNDER].list | J17: ZO_GamepadFenceLaunder | K17: userdata | L17: X | M17: X | N17: ="LibFilters3"&"-shown-"&VLOOKUP(A17,'LibFilters3 filterPanelIds'!$A$3:$B$999,2) & "-" & IF(AND(B17<>"",B17<>"nil"),B17,"") -> LibFilters3-shown-25- | O17: ="LibFilters3"&"-hidden-"&VLOOKUP(A17,'LibFilters3 filterPanelIds'!$A$3:$B$999,2) & "-" & IF(AND(B17<>"",B17<>"nil"),B17,"") -> LibFilters3-hidden-25- | P17: X
A18: LF_FENCE_LAUNDER | C18: =VLOOKUP(A18,'LibFilters3 filterPanelIds'!$A$3:$C$1000,3,FALSE) -> Fence vendor launder | D18: K | J18: BACKPACK_LAUNDER_LAYOUT_FRAGMENT.layoutData | K18: Fragment | L18: X | M18: X | N18: ="LibFilters3"&"-shown-"&VLOOKUP(A18,'LibFilters3 filterPanelIds'!$A$3:$B$999,2) & "-" & IF(AND(B18<>"",B18<>"nil"),B18,"") -> LibFilters3-shown-25- | O18: ="LibFilters3"&"-hidden-"&VLOOKUP(A18,'LibFilters3 filterPanelIds'!$A$3:$B$999,2) & "-" & IF(AND(B18<>"",B18<>"nil"),B18,"") -> LibFilters3-hidden-25- | P18: X
A19: LF_FENCE_SELL | C19: =VLOOKUP(A19,'LibFilters3 filterPanelIds'!$A$3:$C$1000,3,FALSE) -> Fence vendor sell | D19: G | E19: X | F19: \esoui\ingame\storewindow\gamepad\storewindow_gamepad_util.lua | G19: updateFunc | H19: STORE_WINDOW_GAMEPAD.components[ZO_MODE_STORE_SELL_STOLEN].list | J19: ZO_GamepadFenceSell | K19: userdata | L19: X | M19: X | N19: ="LibFilters3"&"-shown-"&VLOOKUP(A19,'LibFilters3 filterPanelIds'!$A$3:$B$999,2) & "-" & IF(AND(B19<>"",B19<>"nil"),B19,"") -> LibFilters3-shown-24- | O19: ="LibFilters3"&"-hidden-"&VLOOKUP(A19,'LibFilters3 filterPanelIds'!$A$3:$B$999,2) & "-" & IF(AND(B19<>"",B19<>"nil"),B19,"") -> LibFilters3-hidden-24- | P19: X
A20: LF_FENCE_SELL | C20: =VLOOKUP(A20,'LibFilters3 filterPanelIds'!$A$3:$C$1000,3,FALSE) -> Fence vendor sell | D20: K | J20: BACKPACK_FENCE_LAYOUT_FRAGMENT.layoutData | K20: Fragment | L20: X | M20: X | N20: ="LibFilters3"&"-shown-"&VLOOKUP(A20,'LibFilters3 filterPanelIds'!$A$3:$B$999,2) & "-" & IF(AND(B20<>"",B20<>"nil"),B20,"") -> LibFilters3-shown-24- | O20: ="LibFilters3"&"-hidden-"&VLOOKUP(A20,'LibFilters3 filterPanelIds'!$A$3:$B$999,2) & "-" & IF(AND(B20<>"",B20<>"nil"),B20,"") -> LibFilters3-hidden-24- | P20: X
A21: LF_FURNITURE_VAULT_DEPOSIT | C21: =VLOOKUP(A21,'LibFilters3 filterPanelIds'!$A$3:$C$1000,3,FALSE) -> Furniture vault Deposit (ESO+ Housing) | D21: G | E21: X | F21: \esoui\ingame\inventory\gamepad\inventorylist_gamepad.lua | G21: AddSlotDataToTable | H21: ZO_GamepadInventoryList | J21: LIBFILTERS3_BACKPACK_FURNITURE_VAULT_DEPOSIT_GAMEPAD_FRAGMENT.layoutData | K21: Custom LibFilters Fragment | M21: X | N21: ="LibFilters3"&"-shown-"&VLOOKUP(A21,'LibFilters3 filterPanelIds'!$A$3:$B$999,2) & "-" & IF(AND(B21<>"",B21<>"nil"),B21,"") -> LibFilters3-shown-41- | O21: ="LibFilters3"&"-hidden-"&VLOOKUP(A21,'LibFilters3 filterPanelIds'!$A$3:$B$999,2) & "-" & IF(AND(B21<>"",B21<>"nil"),B21,"") -> LibFilters3-hidden-41- | P21: X
A22: LF_FURNITURE_VAULT_DEPOSIT | C22: =VLOOKUP(A22,'LibFilters3 filterPanelIds'!$A$3:$C$1000,3,FALSE) -> Furniture vault Deposit (ESO+ Housing) | D22: K | J22: BACKPACK_FURNITURE_VAULT_LAYOUT_FRAGMENT.layoutData | K22: Fragment | L22: X | M22: X | N22: ="LibFilters3"&"-shown-"&VLOOKUP(A22,'LibFilters3 filterPanelIds'!$A$3:$B$999,2) & "-" & IF(AND(B22<>"",B22<>"nil"),B22,"") -> LibFilters3-shown-41- | O22: ="LibFilters3"&"-hidden-"&VLOOKUP(A22,'LibFilters3 filterPanelIds'!$A$3:$B$999,2) & "-" & IF(AND(B22<>"",B22<>"nil"),B22,"") -> LibFilters3-hidden-41- | P22: X
A23: LF_FURNITURE_VAULT_WITHDRAW | C23: =VLOOKUP(A23,'LibFilters3 filterPanelIds'!$A$3:$C$1000,3,FALSE) -> Furniture vault Withdraw (ESO+ Housing) | D23: G | E23: X | F23: \esoui\ingame\inventory\gamepad\inventorylist_gamepad.lua | G23: AddSlotDataToTable | H23: ZO_GamepadInventoryList | J23: PLAYER_INVENTORIES.inventories[INVENTORY_FURNITURE_VAULT] | K23: table (inventory) | L23: X | M23: X | N23: ="LibFilters3"&"-shown-"&VLOOKUP(A23,'LibFilters3 filterPanelIds'!$A$3:$B$999,2) & "-" & IF(AND(B23<>"",B23<>"nil"),B23,"") -> LibFilters3-shown-40- | O23: ="LibFilters3"&"-hidden-"&VLOOKUP(A23,'LibFilters3 filterPanelIds'!$A$3:$B$999,2) & "-" & IF(AND(B23<>"",B23<>"nil"),B23,"") -> LibFilters3-hidden-40- | P23: X | Q23: Fallback to keyboard implementation (means: Uses same objects for .additionalFilter function)
A24: LF_FURNITURE_VAULT_WITHDRAW | C24: =VLOOKUP(A24,'LibFilters3 filterPanelIds'!$A$3:$C$1000,3,FALSE) -> Furniture vault Withdraw (ESO+ Housing) | D24: K | J24: PLAYER_INVENTORIES.inventories[INVENTORY_FURNITURE_VAULT] | K24: table (inventory) | L24: X | M24: X | N24: ="LibFilters3"&"-shown-"&VLOOKUP(A24,'LibFilters3 filterPanelIds'!$A$3:$B$999,2) & "-" & IF(AND(B24<>"",B24<>"nil"),B24,"") -> LibFilters3-shown-40- | O24: ="LibFilters3"&"-hidden-"&VLOOKUP(A24,'LibFilters3 filterPanelIds'!$A$3:$B$999,2) & "-" & IF(AND(B24<>"",B24<>"nil"),B24,"") -> LibFilters3-hidden-40- | P24: X
A25: LF_GUILDBANK_DEPOSIT | C25: =VLOOKUP(A25,'LibFilters3 filterPanelIds'!$A$3:$C$1000,3,FALSE) -> Guildbank Deposit | D25: G | E25: X | F25: \esoui\ingame\inventory\gamepad\inventorylist_gamepad.lua | G25: AddSlotDataToTable | H25: ZO_GamepadInventoryList | J25: LIBFILTERS3_BACKPACK_GUILD_BANK_DEPOSIT_GAMEPAD_FRAGMENT.layoutData | K25: Custom LibFilters Fragment | M25: X | N25: ="LibFilters3"&"-shown-"&VLOOKUP(A25,'LibFilters3 filterPanelIds'!$A$3:$B$999,2) & "-" & IF(AND(B25<>"",B25<>"nil"),B25,"") -> LibFilters3-shown-5- | O25: ="LibFilters3"&"-hidden-"&VLOOKUP(A25,'LibFilters3 filterPanelIds'!$A$3:$B$999,2) & "-" & IF(AND(B25<>"",B25<>"nil"),B25,"") -> LibFilters3-hidden-5- | P25: X
A26: LF_GUILDBANK_DEPOSIT | C26: =VLOOKUP(A26,'LibFilters3 filterPanelIds'!$A$3:$C$1000,3,FALSE) -> Guildbank Deposit | D26: K | J26: BACKPACK_GUILD_BANK_LAYOUT_FRAGMENT.layoutData | K26: Fragment | L26: X | M26: X | N26: ="LibFilters3"&"-shown-"&VLOOKUP(A26,'LibFilters3 filterPanelIds'!$A$3:$B$999,2) & "-" & IF(AND(B26<>"",B26<>"nil"),B26,"") -> LibFilters3-shown-5- | O26: ="LibFilters3"&"-hidden-"&VLOOKUP(A26,'LibFilters3 filterPanelIds'!$A$3:$B$999,2) & "-" & IF(AND(B26<>"",B26<>"nil"),B26,"") -> LibFilters3-hidden-5- | P26: X
A27: LF_GUILDBANK_WITHDRAW | C27: =VLOOKUP(A27,'LibFilters3 filterPanelIds'!$A$3:$C$1000,3,FALSE) -> Guildbank Withdraw | D27: G | E27: X | F27: \esoui\ingame\inventory\gamepad\inventorylist_gamepad.lua | G27: AddSlotDataToTable | H27: ZO_GamepadInventoryList | J27: PLAYER_INVENTORIES.inventories[INVENTORY_GUILD_BANK] | K27: table (inventory) | L27: X | M27: X | N27: ="LibFilters3"&"-shown-"&VLOOKUP(A27,'LibFilters3 filterPanelIds'!$A$3:$B$999,2) & "-" & IF(AND(B27<>"",B27<>"nil"),B27,"") -> LibFilters3-shown-4- | O27: ="LibFilters3"&"-hidden-"&VLOOKUP(A27,'LibFilters3 filterPanelIds'!$A$3:$B$999,2) & "-" & IF(AND(B27<>"",B27<>"nil"),B27,"") -> LibFilters3-hidden-4- | P27: X | Q27: Fallback to keyboard implementation (means: Uses same objects for .additionalFilter function)
A28: LF_GUILDBANK_WITHDRAW | C28: =VLOOKUP(A28,'LibFilters3 filterPanelIds'!$A$3:$C$1000,3,FALSE) -> Guildbank Withdraw | D28: K | J28: PLAYER_INVENTORIES.inventories[INVENTORY_GUILD_BANK] | K28: table (inventory) | L28: X | M28: X | N28: ="LibFilters3"&"-shown-"&VLOOKUP(A28,'LibFilters3 filterPanelIds'!$A$3:$B$999,2) & "-" & IF(AND(B28<>"",B28<>"nil"),B28,"") -> LibFilters3-shown-4- | O28: ="LibFilters3"&"-hidden-"&VLOOKUP(A28,'LibFilters3 filterPanelIds'!$A$3:$B$999,2) & "-" & IF(AND(B28<>"",B28<>"nil"),B28,"") -> LibFilters3-hidden-4- | P28: X
A29: LF_GUILDSTORE_BROWSE | C29: =VLOOKUP(A29,'LibFilters3 filterPanelIds'!$A$3:$C$1000,3,FALSE) -> Guildstore / Tradinghouse Search | D29: B | G29: Currently not implemented | N29: ="LibFilters3"&"-shown-"&VLOOKUP(A29,'LibFilters3 filterPanelIds'!$A$3:$B$999,2) & "-" & IF(AND(B29<>"",B29<>"nil"),B29,"") -> LibFilters3-shown-10- | O29: ="LibFilters3"&"-hidden-"&VLOOKUP(A29,'LibFilters3 filterPanelIds'!$A$3:$B$999,2) & "-" & IF(AND(B29<>"",B29<>"nil"),B29,"") -> LibFilters3-hidden-10- | P29: X
A30: LF_GUILDSTORE_SELL | C30: =VLOOKUP(A30,'LibFilters3 filterPanelIds'!$A$3:$C$1000,3,FALSE) -> Guildstore / Tradinghouse Sell | D30: G | E30: X | F30: \esoui\ingame\inventory\gamepad\inventorylist_gamepad.lua | G30: AddSlotDataToTable | H30: ZO_GamepadInventoryList | J30: LIBFILTERS3_BACKPACK_TRADING_HOUSE_SELL_GAMEPAD_FRAGMENT.layoutData | K30: Custom LibFilters Fragment | M30: X | N30: ="LibFilters3"&"-shown-"&VLOOKUP(A30,'LibFilters3 filterPanelIds'!$A$3:$B$999,2) & "-" & IF(AND(B30<>"",B30<>"nil"),B30,"") -> LibFilters3-shown-11- | O30: ="LibFilters3"&"-hidden-"&VLOOKUP(A30,'LibFilters3 filterPanelIds'!$A$3:$B$999,2) & "-" & IF(AND(B30<>"",B30<>"nil"),B30,"") -> LibFilters3-hidden-11- | P30: X
A31: LF_GUILDSTORE_SELL | C31: =VLOOKUP(A31,'LibFilters3 filterPanelIds'!$A$3:$C$1000,3,FALSE) -> Guildstore / Tradinghouse Sell | D31: K | J31: BACKPACK_TRADING_HOUSE_LAYOUT_FRAGMENT.layoutData | K31: Fragment | L31: X | M31: X | N31: ="LibFilters3"&"-shown-"&VLOOKUP(A31,'LibFilters3 filterPanelIds'!$A$3:$B$999,2) & "-" & IF(AND(B31<>"",B31<>"nil"),B31,"") -> LibFilters3-shown-11- | O31: ="LibFilters3"&"-hidden-"&VLOOKUP(A31,'LibFilters3 filterPanelIds'!$A$3:$B$999,2) & "-" & IF(AND(B31<>"",B31<>"nil"),B31,"") -> LibFilters3-hidden-11- | P31: X
A32: LF_HOUSE_BANK_DEPOSIT | C32: =VLOOKUP(A32,'LibFilters3 filterPanelIds'!$A$3:$C$1000,3,FALSE) -> House bank 1 to 10 Deposit | D32: G | E32: X | F32: \esoui\ingame\inventory\gamepad\inventorylist_gamepad.lua | G32: AddSlotDataToTable | H32: ZO_GamepadInventoryList | J32: LIBFILTERS3_BACKPACK_HOUSE_BANK_DEPOSIT_GAMEPAD_FRAGMENT.layoutData | K32: Custom LibFilters Fragment | M32: X | N32: ="LibFilters3"&"-shown-"&VLOOKUP(A32,'LibFilters3 filterPanelIds'!$A$3:$B$999,2) & "-" & IF(AND(B32<>"",B32<>"nil"),B32,"") -> LibFilters3-shown-30- | O32: ="LibFilters3"&"-hidden-"&VLOOKUP(A32,'LibFilters3 filterPanelIds'!$A$3:$B$999,2) & "-" & IF(AND(B32<>"",B32<>"nil"),B32,"") -> LibFilters3-hidden-30- | P32: X
A33: LF_HOUSE_BANK_DEPOSIT | C33: =VLOOKUP(A33,'LibFilters3 filterPanelIds'!$A$3:$C$1000,3,FALSE) -> House bank 1 to 10 Deposit | D33: K | J33: BACKPACK_HOUSE_BANK_LAYOUT_FRAGMENT.layoutData | K33: Fragment | L33: X | M33: X | N33: ="LibFilters3"&"-shown-"&VLOOKUP(A33,'LibFilters3 filterPanelIds'!$A$3:$B$999,2) & "-" & IF(AND(B33<>"",B33<>"nil"),B33,"") -> LibFilters3-shown-30- | O33: ="LibFilters3"&"-hidden-"&VLOOKUP(A33,'LibFilters3 filterPanelIds'!$A$3:$B$999,2) & "-" & IF(AND(B33<>"",B33<>"nil"),B33,"") -> LibFilters3-hidden-30- | P33: X
A34: LF_HOUSE_BANK_WITHDRAW | C34: =VLOOKUP(A34,'LibFilters3 filterPanelIds'!$A$3:$C$1000,3,FALSE) -> House bank 1 to 10 Withdraw | D34: G | E34: X | F34: \esoui\ingame\inventory\gamepad\inventorylist_gamepad.lua | G34: AddSlotDataToTable | H34: ZO_GamepadInventoryList | J34: PLAYER_INVENTORIES.inventories[INVENTORY_HOUSE_BANK] | K34: table (inventory) | L34: X | M34: X | N34: ="LibFilters3"&"-shown-"&VLOOKUP(A34,'LibFilters3 filterPanelIds'!$A$3:$B$999,2) & "-" & IF(AND(B34<>"",B34<>"nil"),B34,"") -> LibFilters3-shown-29- | O34: ="LibFilters3"&"-hidden-"&VLOOKUP(A34,'LibFilters3 filterPanelIds'!$A$3:$B$999,2) & "-" & IF(AND(B34<>"",B34<>"nil"),B34,"") -> LibFilters3-hidden-29- | P34: X
A35: LF_HOUSE_BANK_WITHDRAW | C35: =VLOOKUP(A35,'LibFilters3 filterPanelIds'!$A$3:$C$1000,3,FALSE) -> House bank 1 to 10 Withdraw | D35: K | J35: PLAYER_INVENTORIES.inventories[INVENTORY_HOUSE_BANK] | K35: table (inventory) | L35: X | M35: X | N35: ="LibFilters3"&"-shown-"&VLOOKUP(A35,'LibFilters3 filterPanelIds'!$A$3:$B$999,2) & "-" & IF(AND(B35<>"",B35<>"nil"),B35,"") -> LibFilters3-shown-29- | O35: ="LibFilters3"&"-hidden-"&VLOOKUP(A35,'LibFilters3 filterPanelIds'!$A$3:$B$999,2) & "-" & IF(AND(B35<>"",B35<>"nil"),B35,"") -> LibFilters3-hidden-29- | P35: X | Q35: Fallback to keyboard implementation (means: Uses same objects for .additionalFilter function)
A36: LF_INVENTORY | C36: =VLOOKUP(A36,'LibFilters3 filterPanelIds'!$A$3:$C$1000,3,FALSE) -> Player inventory | D36: G | E36: X | F36: \esoui\ingame\inventory\gamepad\gamepadinventory.lua | G36: GetItemDataFilterComparator | H36: GAMEPAD_INVENTORY | J36: LIBFILTERS3_BACKPACK_INVENTORY_GAMEPAD_FRAGMENT.layoutData | K36: Custom LibFilters Fragment | M36: X | N36: ="LibFilters3"&"-shown-"&VLOOKUP(A36,'LibFilters3 filterPanelIds'!$A$3:$B$999,2) & "-" & IF(AND(B36<>"",B36<>"nil"),B36,"") -> LibFilters3-shown-1- | O36: ="LibFilters3"&"-hidden-"&VLOOKUP(A36,'LibFilters3 filterPanelIds'!$A$3:$B$999,2) & "-" & IF(AND(B36<>"",B36<>"nil"),B36,"") -> LibFilters3-hidden-1- | P36: X
A37: LF_INVENTORY | C37: =VLOOKUP(A37,'LibFilters3 filterPanelIds'!$A$3:$C$1000,3,FALSE) -> Player inventory | D37: K | G37: [+] None, uses vanilla Zos ZO_InventoryManager:ShouldAddSlotToList -> DoesSlotPassAdditionalFilter | I37: X | J37: BACKPACK_MENU_BAR_LAYOUT_FRAGMENT.layoutData | K37: Fragment | L37: X | M37: X | N37: ="LibFilters3"&"-shown-"&VLOOKUP(A37,'LibFilters3 filterPanelIds'!$A$3:$B$999,2) & "-" & IF(AND(B37<>"",B37<>"nil"),B37,"") -> LibFilters3-shown-1- | O37: ="LibFilters3"&"-hidden-"&VLOOKUP(A37,'LibFilters3 filterPanelIds'!$A$3:$B$999,2) & "-" & IF(AND(B37<>"",B37<>"nil"),B37,"") -> LibFilters3-hidden-1- | P37: X | Q37: 2 hooked objects here because ZO_InventoryManager:ApplyBackpackLayout(layoutData) changes PLAYER_INVENTORY.inventories[INVENTORY_BACKPACK].additionalFilter from layoutData.additionalFilter, where layoutData could be from fragment BACKPACK_MENU_BAR_LAYOUT_FRAGMENT "or others" -> thus we need to hook both
A38: LF_INVENTORY_COMPANION | C38: =VLOOKUP(A38,'LibFilters3 filterPanelIds'!$A$3:$C$1000,3,FALSE) -> Companion inventory (Equipment) | D38: G | E38: X | F38: \esoui_src\live\esoui\ingame\companion\gamepad\companionequipment_gamepad.lua | G38: GetItemDataFilterComparator | H38: COMPANION_EQUIPMENT_GAMEPAD | J38: COMPANION_EQUIPMENT_GAMEPAD | K38: table | L38: X | M38: X | N38: ="LibFilters3"&"-shown-"&VLOOKUP(A38,'LibFilters3 filterPanelIds'!$A$3:$B$999,2) & "-" & IF(AND(B38<>"",B38<>"nil"),B38,"") -> LibFilters3-shown-39- | O38: ="LibFilters3"&"-hidden-"&VLOOKUP(A38,'LibFilters3 filterPanelIds'!$A$3:$B$999,2) & "-" & IF(AND(B38<>"",B38<>"nil"),B38,"") -> LibFilters3-hidden-39- | P38: X
A39: LF_INVENTORY_COMPANION | C39: =VLOOKUP(A39,'LibFilters3 filterPanelIds'!$A$3:$C$1000,3,FALSE) -> Companion inventory (Equipment) | D39: K | G39: [+] None, uses vanilla Zos ZO_InventoryManager:ShouldAddSlotToList -> DoesSlotPassAdditionalFilter | I39: X | J39: COMPANION_EQUIPMENT_KEYBOARD | K39: table | L39: X | M39: X | N39: ="LibFilters3"&"-shown-"&VLOOKUP(A39,'LibFilters3 filterPanelIds'!$A$3:$B$999,2) & "-" & IF(AND(B39<>"",B39<>"nil"),B39,"") -> LibFilters3-shown-39- | O39: ="LibFilters3"&"-hidden-"&VLOOKUP(A39,'LibFilters3 filterPanelIds'!$A$3:$B$999,2) & "-" & IF(AND(B39<>"",B39<>"nil"),B39,"") -> LibFilters3-hidden-39- | P39: X
A40: LF_INVENTORY_QUEST | C40: =VLOOKUP(A40,'LibFilters3 filterPanelIds'!$A$3:$C$1000,3,FALSE) -> Inventory quest items | D40: G | E40: X | F40: \esoui\ingame\inventory\gamepad\gamepadinventory.lua | G40: GetQuestItemDataFilterComparator | H40: GAMEPAD_INVENTORY | J40: LIBFILTERS3_BACKPACK_INVENTORY_QUEST_GAMEPAD_FRAGMENT.layoutData | K40: Custom LibFilters Fragment | M40: X | N40: ="LibFilters3"&"-shown-"&VLOOKUP(A40,'LibFilters3 filterPanelIds'!$A$3:$B$999,2) & "-" & IF(AND(B40<>"",B40<>"nil"),B40,"") -> LibFilters3-shown-38- | O40: ="LibFilters3"&"-hidden-"&VLOOKUP(A40,'LibFilters3 filterPanelIds'!$A$3:$B$999,2) & "-" & IF(AND(B40<>"",B40<>"nil"),B40,"") -> LibFilters3-hidden-38- | P40: X
...

Sheet LibFilters3 helper
A1: LibFilters-3.0 helper.lua: Overwrites vanila ZOs objects/functions/etc. in order to make the filterFunctions work and read the .additionalFilter table at the objects/fragments/scenes/userdata where LibFilters has added them
A3: See tab "LibFilters3 .additionalFilter", columns E (LibFilters helper.lua: Vanilla filename of overwritten function) to G (LibFilters helper.lua: Object/Class/... of overwritten function) for the helper.lua details about the hooked/overwritten object and functions
